[2024-03-02T03:37:05.590+0000] {taskinstance.py:1957} INFO - Dependencies all met for dep_context=non-requeueable deps ti=<TaskInstance: weather_api_dag.get_weather_data scheduled__2024-03-02T02:00:00+00:00 [queued]>
[2024-03-02T03:37:05.600+0000] {taskinstance.py:1957} INFO - Dependencies all met for dep_context=requeueable deps ti=<TaskInstance: weather_api_dag.get_weather_data scheduled__2024-03-02T02:00:00+00:00 [queued]>
[2024-03-02T03:37:05.600+0000] {taskinstance.py:2171} INFO - Starting attempt 1 of 1
[2024-03-02T03:37:05.618+0000] {taskinstance.py:2192} INFO - Executing <Task(PythonOperator): get_weather_data> on 2024-03-02 02:00:00+00:00
[2024-03-02T03:37:05.625+0000] {standard_task_runner.py:60} INFO - Started process 192 to run task
[2024-03-02T03:37:05.628+0000] {standard_task_runner.py:87} INFO - Running: ['***', 'tasks', 'run', 'weather_api_dag', 'get_weather_data', 'scheduled__2024-03-02T02:00:00+00:00', '--job-id', '71', '--raw', '--subdir', 'DAGS_FOLDER/weather_api_dag.py', '--cfg-path', '/tmp/tmpwwzdsd7k']
[2024-03-02T03:37:05.631+0000] {standard_task_runner.py:88} INFO - Job 71: Subtask get_weather_data
[2024-03-02T03:37:05.705+0000] {task_command.py:423} INFO - Running <TaskInstance: weather_api_dag.get_weather_data scheduled__2024-03-02T02:00:00+00:00 [running]> on host 2e037069d2f3
[2024-03-02T03:37:05.843+0000] {taskinstance.py:2481} INFO - Exporting env vars: AIRFLOW_CTX_DAG_EMAIL='kuang.acad@gmail.com' AIRFLOW_CTX_DAG_OWNER='***' AIRFLOW_CTX_DAG_ID='weather_api_dag' AIRFLOW_CTX_TASK_ID='get_weather_data' AIRFLOW_CTX_EXECUTION_DATE='2024-03-02T02:00:00+00:00' AIRFLOW_CTX_TRY_NUMBER='1' AIRFLOW_CTX_DAG_RUN_ID='scheduled__2024-03-02T02:00:00+00:00'
[2024-03-02T03:37:05.869+0000] {taskinstance.py:2699} ERROR - Task failed with exception
Traceback (most recent call last):
  File "/home/airflow/.local/lib/python3.8/site-packages/airflow/models/taskinstance.py", line 433, in _execute_task
    result = execute_callable(context=context, **execute_callable_kwargs)
  File "/home/airflow/.local/lib/python3.8/site-packages/airflow/operators/python.py", line 199, in execute
    return_value = self.execute_callable()
  File "/home/airflow/.local/lib/python3.8/site-packages/airflow/operators/python.py", line 216, in execute_callable
    return self.python_callable(*self.op_args, **self.op_kwargs)
  File "/opt/airflow/dags/weather_api_dag.py", line 16, in _get_weather_data
    name = Variable.get("name")
  File "/home/airflow/.local/lib/python3.8/site-packages/airflow/models/variable.py", line 143, in get
    raise KeyError(f"Variable {key} does not exist")
KeyError: 'Variable name does not exist'
[2024-03-02T03:37:05.879+0000] {taskinstance.py:1138} INFO - Marking task as FAILED. dag_id=weather_api_dag, task_id=get_weather_data, execution_date=20240302T020000, start_date=20240302T033705, end_date=20240302T033705
[2024-03-02T03:37:05.905+0000] {logging_mixin.py:188} WARNING - /home/***/.local/lib/python3.8/site-packages/***/utils/email.py:154 RemovedInAirflow3Warning: Fetching SMTP credentials from configuration variables will be deprecated in a future release. Please set credentials using a connection instead.
[2024-03-02T03:37:05.905+0000] {configuration.py:1046} WARNING - section/key [smtp/smtp_user] not found in config
[2024-03-02T03:37:05.905+0000] {email.py:270} INFO - Email alerting: attempt 1
[2024-03-02T03:37:05.908+0000] {email.py:281} INFO - Sent an alert email to ['kuang.acad@gmail.com']
[2024-03-02T03:37:05.952+0000] {standard_task_runner.py:107} ERROR - Failed to execute job 71 for task get_weather_data ('Variable name does not exist'; 192)
[2024-03-02T03:37:05.973+0000] {local_task_job_runner.py:234} INFO - Task exited with return code 1
[2024-03-02T03:37:06.011+0000] {taskinstance.py:3281} INFO - 0 downstream tasks scheduled from follow-on schedule check
