[2024-02-10T04:12:49.005+0000] {taskinstance.py:1957} INFO - Dependencies all met for dep_context=non-requeueable deps ti=<TaskInstance: weather_api_dag.get_weather_data backfill__2024-02-09T00:00:00+00:00 [queued]>
[2024-02-10T04:12:49.124+0000] {taskinstance.py:1957} INFO - Dependencies all met for dep_context=requeueable deps ti=<TaskInstance: weather_api_dag.get_weather_data backfill__2024-02-09T00:00:00+00:00 [queued]>
[2024-02-10T04:12:49.125+0000] {taskinstance.py:2171} INFO - Starting attempt 1 of 1
[2024-02-10T04:12:49.428+0000] {taskinstance.py:2192} INFO - Executing <Task(PythonOperator): get_weather_data> on 2024-02-09 00:00:00+00:00
[2024-02-10T04:12:49.579+0000] {standard_task_runner.py:60} INFO - Started process 5055 to run task
[2024-02-10T04:12:49.624+0000] {standard_task_runner.py:87} INFO - Running: ['***', 'tasks', 'run', 'weather_api_dag', 'get_weather_data', 'backfill__2024-02-09T00:00:00+00:00', '--job-id', '40', '--pool', 'default_pool', '--raw', '--subdir', 'DAGS_FOLDER/weather_api_dag.py', '--cfg-path', '/tmp/tmp03xdi2px']
[2024-02-10T04:12:49.712+0000] {standard_task_runner.py:88} INFO - Job 40: Subtask get_weather_data
[2024-02-10T04:12:50.238+0000] {task_command.py:423} INFO - Running <TaskInstance: weather_api_dag.get_weather_data backfill__2024-02-09T00:00:00+00:00 [running]> on host 442b6bee1a9c
[2024-02-10T04:12:51.193+0000] {taskinstance.py:2481} INFO - Exporting env vars: AIRFLOW_CTX_DAG_EMAIL='tharathip.kul@gmail.com' AIRFLOW_CTX_DAG_OWNER='***' AIRFLOW_CTX_DAG_ID='weather_api_dag' AIRFLOW_CTX_TASK_ID='get_weather_data' AIRFLOW_CTX_EXECUTION_DATE='2024-02-09T00:00:00+00:00' AIRFLOW_CTX_TRY_NUMBER='1' AIRFLOW_CTX_DAG_RUN_ID='backfill__2024-02-09T00:00:00+00:00'
[2024-02-10T04:12:51.973+0000] {logging_mixin.py:188} INFO - {'coord': {'lon': 100.5167, 'lat': 13.75}, 'weather': [{'id': 804, 'main': 'Clouds', 'description': 'overcast clouds', 'icon': '04d'}], 'base': 'stations', 'main': {'temp': 303.63, 'feels_like': 310.63, 'temp_min': 302, 'temp_max': 305.88, 'pressure': 1016, 'humidity': 82}, 'visibility': 7289, 'wind': {'speed': 3.75, 'deg': 96, 'gust': 4.9}, 'clouds': {'all': 89}, 'dt': 1707538236, 'sys': {'type': 2, 'id': 2031980, 'country': 'TH', 'sunrise': 1707522198, 'sunset': 1707564066}, 'timezone': 25200, 'id': 1609350, 'name': 'Bangkok', 'cod': 200}
[2024-02-10T04:12:52.575+0000] {taskinstance.py:2699} ERROR - Task failed with exception
Traceback (most recent call last):
  File "/home/airflow/.local/lib/python3.8/site-packages/requests/models.py", line 971, in json
    return complexjson.loads(self.text, **kwargs)
  File "/usr/local/lib/python3.8/json/__init__.py", line 357, in loads
    return _default_decoder.decode(s)
  File "/usr/local/lib/python3.8/json/decoder.py", line 337, in decode
    obj, end = self.raw_decode(s, idx=_w(s, 0).end())
  File "/usr/local/lib/python3.8/json/decoder.py", line 355, in raw_decode
    raise JSONDecodeError("Expecting value", s, err.value) from None
json.decoder.JSONDecodeError: Expecting value: line 1 column 1 (char 0)

During handling of the above exception, another exception occurred:

Traceback (most recent call last):
  File "/home/airflow/.local/lib/python3.8/site-packages/airflow/models/taskinstance.py", line 433, in _execute_task
    result = execute_callable(context=context, **execute_callable_kwargs)
  File "/home/airflow/.local/lib/python3.8/site-packages/airflow/operators/python.py", line 199, in execute
    return_value = self.execute_callable()
  File "/home/airflow/.local/lib/python3.8/site-packages/airflow/operators/python.py", line 216, in execute_callable
    return self.python_callable(*self.op_args, **self.op_kwargs)
  File "/opt/airflow/dags/weather_api_dag.py", line 45, in _get_weather_data
    print(response.json())
  File "/home/airflow/.local/lib/python3.8/site-packages/requests/models.py", line 975, in json
    raise RequestsJSONDecodeError(e.msg, e.doc, e.pos)
requests.exceptions.JSONDecodeError: Expecting value: line 1 column 1 (char 0)
[2024-02-10T04:12:52.720+0000] {taskinstance.py:1138} INFO - Marking task as FAILED. dag_id=weather_api_dag, task_id=get_weather_data, execution_date=20240209T000000, start_date=20240210T041249, end_date=20240210T041252
[2024-02-10T04:12:53.049+0000] {logging_mixin.py:188} WARNING - /home/***/.local/lib/python3.8/site-packages/***/utils/email.py:154 RemovedInAirflow3Warning: Fetching SMTP credentials from configuration variables will be deprecated in a future release. Please set credentials using a connection instead.
[2024-02-10T04:12:53.054+0000] {configuration.py:1046} WARNING - section/key [smtp/smtp_user] not found in config
[2024-02-10T04:12:53.055+0000] {email.py:270} INFO - Email alerting: attempt 1
[2024-02-10T04:12:53.066+0000] {email.py:281} INFO - Sent an alert email to ['tharathip.kul@gmail.com']
[2024-02-10T04:12:53.221+0000] {standard_task_runner.py:107} ERROR - Failed to execute job 40 for task get_weather_data (Expecting value: line 1 column 1 (char 0); 5055)
[2024-02-10T04:12:53.295+0000] {local_task_job_runner.py:234} INFO - Task exited with return code 1
[2024-02-10T04:12:53.452+0000] {taskinstance.py:3281} INFO - 0 downstream tasks scheduled from follow-on schedule check
