[2024-02-10T04:59:58.480+0000] {taskinstance.py:1957} INFO - Dependencies all met for dep_context=non-requeueable deps ti=<TaskInstance: weather_api_dag.get_weather_data manual__2024-02-10T04:58:42.390667+00:00 [queued]>
[2024-02-10T04:59:58.486+0000] {taskinstance.py:1957} INFO - Dependencies all met for dep_context=requeueable deps ti=<TaskInstance: weather_api_dag.get_weather_data manual__2024-02-10T04:58:42.390667+00:00 [queued]>
[2024-02-10T04:59:58.486+0000] {taskinstance.py:2171} INFO - Starting attempt 2 of 2
[2024-02-10T04:59:58.502+0000] {taskinstance.py:2192} INFO - Executing <Task(PythonOperator): get_weather_data> on 2024-02-10 04:58:42.390667+00:00
[2024-02-10T04:59:58.507+0000] {standard_task_runner.py:60} INFO - Started process 9009 to run task
[2024-02-10T04:59:58.510+0000] {standard_task_runner.py:87} INFO - Running: ['***', 'tasks', 'run', 'weather_api_dag', 'get_weather_data', 'manual__2024-02-10T04:58:42.390667+00:00', '--job-id', '66', '--raw', '--subdir', 'DAGS_FOLDER/weather_api_dag.py', '--cfg-path', '/tmp/tmpp17s2six']
[2024-02-10T04:59:58.512+0000] {standard_task_runner.py:88} INFO - Job 66: Subtask get_weather_data
[2024-02-10T04:59:58.552+0000] {task_command.py:423} INFO - Running <TaskInstance: weather_api_dag.get_weather_data manual__2024-02-10T04:58:42.390667+00:00 [running]> on host 442b6bee1a9c
[2024-02-10T04:59:58.624+0000] {taskinstance.py:2481} INFO - Exporting env vars: AIRFLOW_CTX_DAG_EMAIL='kuang.acad@gmail.com' AIRFLOW_CTX_DAG_OWNER='***' AIRFLOW_CTX_DAG_ID='weather_api_dag' AIRFLOW_CTX_TASK_ID='get_weather_data' AIRFLOW_CTX_EXECUTION_DATE='2024-02-10T04:58:42.390667+00:00' AIRFLOW_CTX_TRY_NUMBER='2' AIRFLOW_CTX_DAG_RUN_ID='manual__2024-02-10T04:58:42.390667+00:00'
[2024-02-10T04:59:58.635+0000] {taskinstance.py:2699} ERROR - Task failed with exception
Traceback (most recent call last):
  File "/home/airflow/.local/lib/python3.8/site-packages/airflow/models/taskinstance.py", line 433, in _execute_task
    result = execute_callable(context=context, **execute_callable_kwargs)
  File "/home/airflow/.local/lib/python3.8/site-packages/airflow/operators/python.py", line 199, in execute
    return_value = self.execute_callable()
  File "/home/airflow/.local/lib/python3.8/site-packages/airflow/operators/python.py", line 216, in execute_callable
    return self.python_callable(*self.op_args, **self.op_kwargs)
  File "/opt/airflow/dags/weather_api_dag.py", line 16, in _get_weather_data
    name = Variable.get("name")
  File "/home/airflow/.local/lib/python3.8/site-packages/airflow/models/variable.py", line 143, in get
    raise KeyError(f"Variable {key} does not exist")
KeyError: 'Variable name does not exist'
[2024-02-10T04:59:58.643+0000] {taskinstance.py:1138} INFO - Marking task as FAILED. dag_id=weather_api_dag, task_id=get_weather_data, execution_date=20240210T045842, start_date=20240210T045958, end_date=20240210T045958
[2024-02-10T04:59:58.655+0000] {logging_mixin.py:188} WARNING - /home/***/.local/lib/python3.8/site-packages/***/utils/email.py:154 RemovedInAirflow3Warning: Fetching SMTP credentials from configuration variables will be deprecated in a future release. Please set credentials using a connection instead.
[2024-02-10T04:59:58.656+0000] {configuration.py:1046} WARNING - section/key [smtp/smtp_user] not found in config
[2024-02-10T04:59:58.656+0000] {email.py:270} INFO - Email alerting: attempt 1
[2024-02-10T04:59:58.658+0000] {email.py:281} INFO - Sent an alert email to ['kuang.acad@gmail.com']
[2024-02-10T04:59:58.681+0000] {standard_task_runner.py:107} ERROR - Failed to execute job 66 for task get_weather_data ('Variable name does not exist'; 9009)
[2024-02-10T04:59:58.724+0000] {local_task_job_runner.py:234} INFO - Task exited with return code 1
[2024-02-10T04:59:58.742+0000] {taskinstance.py:3281} INFO - 0 downstream tasks scheduled from follow-on schedule check
