[2024-01-31T12:25:26.528+0000] {taskinstance.py:1957} INFO - Dependencies all met for dep_context=non-requeueable deps ti=<TaskInstance: weather_api_dag.get_weather_data scheduled__2024-01-31T11:00:00+00:00 [queued]>
[2024-01-31T12:25:26.560+0000] {taskinstance.py:1957} INFO - Dependencies all met for dep_context=requeueable deps ti=<TaskInstance: weather_api_dag.get_weather_data scheduled__2024-01-31T11:00:00+00:00 [queued]>
[2024-01-31T12:25:26.562+0000] {taskinstance.py:2171} INFO - Starting attempt 1 of 1
[2024-01-31T12:25:26.628+0000] {taskinstance.py:2192} INFO - Executing <Task(PythonOperator): get_weather_data> on 2024-01-31 11:00:00+00:00
[2024-01-31T12:25:26.638+0000] {standard_task_runner.py:60} INFO - Started process 40180 to run task
[2024-01-31T12:25:26.646+0000] {standard_task_runner.py:87} INFO - Running: ['***', 'tasks', 'run', 'weather_api_dag', 'get_weather_data', 'scheduled__2024-01-31T11:00:00+00:00', '--job-id', '114', '--raw', '--subdir', 'DAGS_FOLDER/weather_api_dag.py', '--cfg-path', '/tmp/tmpiruzin9w']
[2024-01-31T12:25:26.653+0000] {standard_task_runner.py:88} INFO - Job 114: Subtask get_weather_data
[2024-01-31T12:25:26.772+0000] {task_command.py:423} INFO - Running <TaskInstance: weather_api_dag.get_weather_data scheduled__2024-01-31T11:00:00+00:00 [running]> on host 68c8327b56d3
[2024-01-31T12:25:27.058+0000] {taskinstance.py:2481} INFO - Exporting env vars: AIRFLOW_CTX_DAG_OWNER='***' AIRFLOW_CTX_DAG_ID='weather_api_dag' AIRFLOW_CTX_TASK_ID='get_weather_data' AIRFLOW_CTX_EXECUTION_DATE='2024-01-31T11:00:00+00:00' AIRFLOW_CTX_TRY_NUMBER='1' AIRFLOW_CTX_DAG_RUN_ID='scheduled__2024-01-31T11:00:00+00:00'
[2024-01-31T12:25:27.081+0000] {taskinstance.py:2699} ERROR - Task failed with exception
Traceback (most recent call last):
  File "/home/airflow/.local/lib/python3.8/site-packages/airflow/models/taskinstance.py", line 433, in _execute_task
    result = execute_callable(context=context, **execute_callable_kwargs)
  File "/home/airflow/.local/lib/python3.8/site-packages/airflow/operators/python.py", line 199, in execute
    return_value = self.execute_callable()
  File "/home/airflow/.local/lib/python3.8/site-packages/airflow/operators/python.py", line 216, in execute_callable
    return self.python_callable(*self.op_args, **self.op_kwargs)
  File "/opt/airflow/dags/weather_api_dag.py", line 14, in _get_weather_data
    api_key = Variable.get("api_key")
  File "/home/airflow/.local/lib/python3.8/site-packages/airflow/models/variable.py", line 143, in get
    raise KeyError(f"Variable {key} does not exist")
KeyError: 'Variable api_key does not exist'
[2024-01-31T12:25:27.108+0000] {taskinstance.py:1138} INFO - Marking task as FAILED. dag_id=weather_api_dag, task_id=get_weather_data, execution_date=20240131T110000, start_date=20240131T122526, end_date=20240131T122527
[2024-01-31T12:25:27.143+0000] {standard_task_runner.py:107} ERROR - Failed to execute job 114 for task get_weather_data ('Variable api_key does not exist'; 40180)
[2024-01-31T12:25:27.185+0000] {local_task_job_runner.py:234} INFO - Task exited with return code 1
[2024-01-31T12:25:27.265+0000] {taskinstance.py:3281} INFO - 0 downstream tasks scheduled from follow-on schedule check
